Workbook
Name Slicer_Category: #N/A
Name Slicer_Customer_City: #N/A
Name Slicer_Status: #N/A

Sheet Orders
A1: Order_ID | B1: Customer_ID | C1: Product_ID | D1: Quantity | E1: Order_Date | F1: Status | G1: Product name | H1: Category | I1: Unit_price | J1: Customer_name | K1: Customer_City | L1: Membership | M1: Total_Revenue | N1: Supplier City | P1: Total Revenue | Q1: ='Pivot Tables'!K85 -> 21520
A2: O001 | B2: C012 | C2: P05 | D2: 2 | E2: 46113 | F2: Delivered | G2: =VLOOKUP(C2,Products!A:E,2,0) -> Laptop Stand | H2: =VLOOKUP(C2,Products!A:E,3,0) -> Electronics | I2: =VLOOKUP(C2,Products!A:E,4,0) -> 40 | J2: =_xlfn.XLOOKUP(B2,Customers!A:A,Customers!B:B) -> Mariam Javed | K2: =_xlfn.XLOOKUP(B2,Customers!A:A,Customers!C:C) -> Rawalpindi | L2: =_xlfn.XLOOKUP(B2,Customers!A:A,Customers!D:D) -> Bronze | M2: =D2*I2 -> 80 | N2: =_xlfn.XLOOKUP(C2,Products!A:A,Products!E:E) -> Rawalpindi | P2: Total Orders | Q2: ='Pivot Tables'!L85 -> 94
A3: O002 | B3: C034 | C3: P12 | D3: 1 | E3: 46113 | F3: Delivered | G3: =VLOOKUP(C3,Products!A:E,2,0) -> Air Fryer | H3: =VLOOKUP(C3,Products!A:E,3,0) -> Home & Kitchen | I3: =VLOOKUP(C3,Products!A:E,4,0) -> 150 | J3: =_xlfn.XLOOKUP(B3,Customers!A:A,Customers!B:B) -> Rabia Tariq | K3: =_xlfn.XLOOKUP(B3,Customers!A:A,Customers!C:C) -> Karachi | L3: =_xlfn.XLOOKUP(B3,Customers!A:A,Customers!D:D) -> Gold | M3: =D3*I3 -> 150 | N3: =_xlfn.XLOOKUP(C3,Products!A:A,Products!E:E) -> Lahore | P3: Avg Order Value | Q3: =IFERROR(Q1/Q2,"-") -> 228.93617
A4: O003 | B4: C007 | C4: P03 | D4: 3 | E4: 46114 | F4: Delivered | G4: =VLOOKUP(C4,Products!A:E,2,0) -> Phone Case | H4: =VLOOKUP(C4,Products!A:E,3,0) -> Electronics | I4: =VLOOKUP(C4,Products!A:E,4,0) -> 12 | J4: =_xlfn.XLOOKUP(B4,Customers!A:A,Customers!B:B) -> Omar Tariq | K4: =_xlfn.XLOOKUP(B4,Customers!A:A,Customers!C:C) -> Karachi | L4: =_xlfn.XLOOKUP(B4,Customers!A:A,Customers!D:D) -> Gold | M4: =D4*I4 -> 36 | N4: =_xlfn.XLOOKUP(C4,Products!A:A,Products!E:E) -> Islamabad | P4: Top City | Q4: =INDEX(P6:P10,MATCH(MAX(Q6:Q10),Q6:Q10,0)) -> Lahore
A5: O004 | B5: C021 | C5: P08 | D5: 1 | E5: 46114 | F5: Returned | G5: =VLOOKUP(C5,Products!A:E,2,0) -> Hair Serum | H5: =VLOOKUP(C5,Products!A:E,3,0) -> Beauty | I5: =VLOOKUP(C5,Products!A:E,4,0) -> 35 | J5: =_xlfn.XLOOKUP(B5,Customers!A:A,Customers!B:B) -> Faisal Chaudhry | K5: =_xlfn.XLOOKUP(B5,Customers!A:A,Customers!C:C) -> Islamabad | L5: =_xlfn.XLOOKUP(B5,Customers!A:A,Customers!D:D) -> Bronze | M5: =D5*I5 -> 35 | N5: =_xlfn.XLOOKUP(C5,Products!A:A,Products!E:E) -> Islamabad
A6: O005 | B6: C045 | C6: P15 | D6: 2 | E6: 46115 | F6: Delivered | G6: =VLOOKUP(C6,Products!A:E,2,0) -> Kettle | H6: =VLOOKUP(C6,Products!A:E,3,0) -> Home & Kitchen | I6: =VLOOKUP(C6,Products!A:E,4,0) -> 65 | J6: =_xlfn.XLOOKUP(B6,Customers!A:A,Customers!B:B) -> Maryam Shah | K6: =_xlfn.XLOOKUP(B6,Customers!A:A,Customers!C:C) -> Karachi | L6: =_xlfn.XLOOKUP(B6,Customers!A:A,Customers!D:D) -> Bronze | M6: =D6*I6 -> 130 | N6: =_xlfn.XLOOKUP(C6,Products!A:A,Products!E:E) -> Karachi | P6: Lahore | Q6: =SUMIF(K2:K301,"Lahore",M2:M301) -> 11000
A7: O006 | B7: C003 | C7: P07 | D7: 4 | E7: 46115 | F7: Delivered | G7: =VLOOKUP(C7,Products!A:E,2,0) -> Sunscreen | H7: =VLOOKUP(C7,Products!A:E,3,0) -> Beauty | I7: =VLOOKUP(C7,Products!A:E,4,0) -> 15 | J7: =_xlfn.XLOOKUP(B7,Customers!A:A,Customers!B:B) -> Bilal Raza | K7: =_xlfn.XLOOKUP(B7,Customers!A:A,Customers!C:C) -> Islamabad | L7: =_xlfn.XLOOKUP(B7,Customers!A:A,Customers!D:D) -> Bronze | M7: =D7*I7 -> 60 | N7: =_xlfn.XLOOKUP(C7,Products!A:A,Products!E:E) -> Karachi | P7: Karachi | Q7: =SUMIF(K2:K301,"Karachi",M2:M301) -> 10944
A8: O007 | B8: C018 | C8: P02 | D8: 1 | E8: 46116 | F8: Pending | G8: =VLOOKUP(C8,Products!A:E,2,0) -> Wireless Earbuds | H8: =VLOOKUP(C8,Products!A:E,3,0) -> Electronics | I8: =VLOOKUP(C8,Products!A:E,4,0) -> 45 | J8: =_xlfn.XLOOKUP(B8,Customers!A:A,Customers!B:B) -> Amna Rizvi | K8: =_xlfn.XLOOKUP(B8,Customers!A:A,Customers!C:C) -> Lahore | L8: =_xlfn.XLOOKUP(B8,Customers!A:A,Customers!D:D) -> Bronze | M8: =D8*I8 -> 45 | N8: =_xlfn.XLOOKUP(C8,Products!A:A,Products!E:E) -> Lahore | P8: Islamabad | Q8: =SUMIF(K2:K301,"Islamabad",M2:M301) -> 6432
A9: O008 | B9: C029 | C9: P11 | D9: 1 | E9: 46116 | F9: Delivered | G9: =VLOOKUP(C9,Products!A:E,2,0) -> Coffee Maker | H9: =VLOOKUP(C9,Products!A:E,3,0) -> Home & Kitchen | I9: =VLOOKUP(C9,Products!A:E,4,0) -> 110 | J9: =_xlfn.XLOOKUP(B9,Customers!A:A,Customers!B:B) -> Sana Malik | K9: =_xlfn.XLOOKUP(B9,Customers!A:A,Customers!C:C) -> Lahore | L9: =_xlfn.XLOOKUP(B9,Customers!A:A,Customers!D:D) -> Silver | M9: =D9*I9 -> 110 | N9: =_xlfn.XLOOKUP(C9,Products!A:A,Products!E:E) -> Karachi | P9: Rawalpindi | Q9: =SUMIF(K2:K301,"Rawalpindi",M2:M301) -> 5527
A10: O009 | B10: C041 | C10: P06 | D10: 5 | E10: 46117 | F10: Delivered | G10: =VLOOKUP(C10,Products!A:E,2,0) -> Face Serum | H10: =VLOOKUP(C10,Products!A:E,3,0) -> Beauty | I10: =VLOOKUP(C10,Products!A:E,4,0) -> 30 | J10: =_xlfn.XLOOKUP(B10,Customers!A:A,Customers!B:B) -> Farah Noor | K10: =_xlfn.XLOOKUP(B10,Customers!A:A,Customers!C:C) -> Karachi | L10: =_xlfn.XLOOKUP(B10,Customers!A:A,Customers!D:D) -> Silver | M10: =D10*I10 -> 150 | N10: =_xlfn.XLOOKUP(C10,Products!A:A,Products!E:E) -> Lahore | P10: Faisalabad | Q10: =SUMIF(K2:K301,"Faisalabad",M2:M301) -> 3584
A11: O010 | B11: C015 | C11: P14 | D11: 3 | E11: 46117 | F11: Returned | G11: =VLOOKUP(C11,Products!A:E,2,0) -> Rice Cooker | H11: =VLOOKUP(C11,Products!A:E,3,0) -> Home & Kitchen | I11: =VLOOKUP(C11,Products!A:E,4,0) -> 95 | J11: =_xlfn.XLOOKUP(B11,Customers!A:A,Customers!B:B) -> Talha Mirza | K11: =_xlfn.XLOOKUP(B11,Customers!A:A,Customers!C:C) -> Lahore | L11: =_xlfn.XLOOKUP(B11,Customers!A:A,Customers!D:D) -> Bronze | M11: =D11*I11 -> 285 | N11: =_xlfn.XLOOKUP(C11,Products!A:A,Products!E:E) -> Rawalpindi
A12: O011 | B12: C008 | C12: P01 | D12: 1 | E12: 46118 | F12: Delivered | G12: =VLOOKUP(C12,Products!A:E,2,0) -> Smart Watch | H12: =VLOOKUP(C12,Products!A:E,3,0) -> Electronics | I12: =VLOOKUP(C12,Products!A:E,4,0) -> 200 | J12: =_xlfn.XLOOKUP(B12,Customers!A:A,Customers!B:B) -> Ayesha Siddiqui | K12: =_xlfn.XLOOKUP(B12,Customers!A:A,Customers!C:C) -> Islamabad | L12: =_xlfn.XLOOKUP(B12,Customers!A:A,Customers!D:D) -> Silver | M12: =D12*I12 -> 200 | N12: =_xlfn.XLOOKUP(C12,Products!A:A,Products!E:E) -> Karachi
A13: O012 | B13: C037 | C13: P09 | D13: 1 | E13: 46118 | F13: Delivered | G13: =VLOOKUP(C13,Products!A:E,2,0) -> Moisturizer | H13: =VLOOKUP(C13,Products!A:E,3,0) -> Beauty | I13: =VLOOKUP(C13,Products!A:E,4,0) -> 25 | J13: =_xlfn.XLOOKUP(B13,Customers!A:A,Customers!B:B) -> Ali Hussain | K13: =_xlfn.XLOOKUP(B13,Customers!A:A,Customers!C:C) -> Karachi | L13: =_xlfn.XLOOKUP(B13,Customers!A:A,Customers!D:D) -> Gold | M13: =D13*I13 -> 25 | N13: =_xlfn.XLOOKUP(C13,Products!A:A,Products!E:E) -> Lahore | P13: Delivery Rate | Q13: =COUNTIF(F2:F301,"Delivered")/COUNTA(F2:F301) -> 0.88
A14: O013 | B14: C022 | C14: P13 | D14: 2 | E14: 46119 | F14: Delivered | G14: =VLOOKUP(C14,Products!A:E,2,0) -> Blender | H14: =VLOOKUP(C14,Products!A:E,3,0) -> Home & Kitchen | I14: =VLOOKUP(C14,Products!A:E,4,0) -> 120 | J14: =_xlfn.XLOOKUP(B14,Customers!A:A,Customers!B:B) -> Noor Fatima | K14: =_xlfn.XLOOKUP(B14,Customers!A:A,Customers!C:C) -> Lahore | L14: =_xlfn.XLOOKUP(B14,Customers!A:A,Customers!D:D) -> Gold | M14: =D14*I14 -> 240 | N14: =_xlfn.XLOOKUP(C14,Products!A:A,Products!E:E) -> Islamabad
A15: O014 | B15: C006 | C15: P04 | D15: 1 | E15: 46119 | F15: Pending | G15: =VLOOKUP(C15,Products!A:E,2,0) -> Bluetooth Speaker | H15: =VLOOKUP(C15,Products!A:E,3,0) -> Electronics | I15: =VLOOKUP(C15,Products!A:E,4,0) -> 95 | J15: =_xlfn.XLOOKUP(B15,Customers!A:A,Customers!B:B) -> Zainab Hussain | K15: =_xlfn.XLOOKUP(B15,Customers!A:A,Customers!C:C) -> Lahore | L15: =_xlfn.XLOOKUP(B15,Customers!A:A,Customers!D:D) -> Bronze | M15: =D15*I15 -> 95 | N15: =_xlfn.XLOOKUP(C15,Products!A:A,Products!E:E) -> Karachi | P15: Quanity Sold | Q15: ='Pivot Tables'!M85 -> 185
A16: O015 | B16: C033 | C16: P10 | D16: 2 | E16: 46120 | F16: Delivered | G16: =VLOOKUP(C16,Products!A:E,2,0) -> Night Cream | H16: =VLOOKUP(C16,Products!A:E,3,0) -> Beauty | I16: =VLOOKUP(C16,Products!A:E,4,0) -> 40 | J16: =_xlfn.XLOOKUP(B16,Customers!A:A,Customers!B:B) -> Bilal Sheikh | K16: =_xlfn.XLOOKUP(B16,Customers!A:A,Customers!C:C) -> Rawalpindi | L16: =_xlfn.XLOOKUP(B16,Customers!A:A,Customers!D:D) -> Bronze | M16: =D16*I16 -> 80 | N16: =_xlfn.XLOOKUP(C16,Products!A:A,Products!E:E) -> Faisalabad
A17: O016 | B17: C044 | C17: P07 | D17: 2 | E17: 46120 | F17: Delivered | G17: =VLOOKUP(C17,Products!A:E,2,0) -> Sunscreen | H17: =VLOOKUP(C17,Products!A:E,3,0) -> Beauty | I17: =VLOOKUP(C17,Products!A:E,4,0) -> 15 | J17: =_xlfn.XLOOKUP(B17,Customers!A:A,Customers!B:B) -> Omer Farooq | K17: =_xlfn.XLOOKUP(B17,Customers!A:A,Customers!C:C) -> Islamabad | L17: =_xlfn.XLOOKUP(B17,Customers!A:A,Customers!D:D) -> Silver | M17: =D17*I17 -> 30 | N17: =_xlfn.XLOOKUP(C17,Products!A:A,Products!E:E) -> Karachi
A18: O017 | B18: C011 | C18: P03 | D18: 1 | E18: 46121 | F18: Delivered | G18: =VLOOKUP(C18,Products!A:E,2,0) -> Phone Case | H18: =VLOOKUP(C18,Products!A:E,3,0) -> Electronics | I18: =VLOOKUP(C18,Products!A:E,4,0) -> 12 | J18: =_xlfn.XLOOKUP(B18,Customers!A:A,Customers!B:B) -> Hamza Tariq | K18: =_xlfn.XLOOKUP(B18,Customers!A:A,Customers!C:C) -> Karachi | L18: =_xlfn.XLOOKUP(B18,Customers!A:A,Customers!D:D) -> Silver | M18: =D18*I18 -> 12 | N18: =_xlfn.XLOOKUP(C18,Products!A:A,Products!E:E) -> Islamabad
A19: O018 | B19: C028 | C19: P08 | D19: 1 | E19: 46121 | F19: Delivered | G19: =VLOOKUP(C19,Products!A:E,2,0) -> Hair Serum | H19: =VLOOKUP(C19,Products!A:E,3,0) -> Beauty | I19: =VLOOKUP(C19,Products!A:E,4,0) -> 35 | J19: =_xlfn.XLOOKUP(B19,Customers!A:A,Customers!B:B) -> Tariq Mehmood | K19: =_xlfn.XLOOKUP(B19,Customers!A:A,Customers!C:C) -> Islamabad | L19: =_xlfn.XLOOKUP(B19,Customers!A:A,Customers!D:D) -> Gold | M19: =D19*I19 -> 35 | N19: =_xlfn.XLOOKUP(C19,Products!A:A,Products!E:E) -> Islamabad
A20: O019 | B20: C002 | C20: P12 | D20: 3 | E20: 46122 | F20: Delivered | G20: =VLOOKUP(C20,Products!A:E,2,0) -> Air Fryer | H20: =VLOOKUP(C20,Products!A:E,3,0) -> Home & Kitchen | I20: =VLOOKUP(C20,Products!A:E,4,0) -> 150 | J20: =_xlfn.XLOOKUP(B20,Customers!A:A,Customers!B:B) -> Sara Ali | K20: =_xlfn.XLOOKUP(B20,Customers!A:A,Customers!C:C) -> Lahore | L20: =_xlfn.XLOOKUP(B20,Customers!A:A,Customers!D:D) -> Silver | M20: =D20*I20 -> 450 | N20: =_xlfn.XLOOKUP(C20,Products!A:A,Products!E:E) -> Lahore
A21: O020 | B21: C039 | C21: P05 | D21: 2 | E21: 46122 | F21: Returned | G21: =VLOOKUP(C21,Products!A:E,2,0) -> Laptop Stand | H21: =VLOOKUP(C21,Products!A:E,3,0) -> Electronics | I21: =VLOOKUP(C21,Products!A:E,4,0) -> 40 | J21: =_xlfn.XLOOKUP(B21,Customers!A:A,Customers!B:B) -> Zara Malik | K21: =_xlfn.XLOOKUP(B21,Customers!A:A,Customers!C:C) -> Islamabad | L21: =_xlfn.XLOOKUP(B21,Customers!A:A,Customers!D:D) -> Bronze | M21: =D21*I21 -> 80 | N21: =_xlfn.XLOOKUP(C21,Products!A:A,Products!E:E) -> Rawalpindi
A22: O021 | B22: C016 | C22: P11 | D22: 2 | E22: 46123 | F22: Pending | G22: =VLOOKUP(C22,Products!A:E,2,0) -> Coffee Maker | H22: =VLOOKUP(C22,Products!A:E,3,0) -> Home & Kitchen | I22: =VLOOKUP(C22,Products!A:E,4,0) -> 110 | J22: =_xlfn.XLOOKUP(B22,Customers!A:A,Customers!B:B) -> Rabia Noor | K22: =_xlfn.XLOOKUP(B22,Customers!A:A,Customers!C:C) -> Karachi | L22: =_xlfn.XLOOKUP(B22,Customers!A:A,Customers!D:D) -> Gold | M22: =D22*I22 -> 220 | N22: =_xlfn.XLOOKUP(C22,Products!A:A,Products!E:E) -> Karachi
A23: O022 | B23: C031 | C23: P06 | D23: 1 | E23: 46123 | F23: Delivered | G23: =VLOOKUP(C23,Products!A:E,2,0) -> Face Serum | H23: =VLOOKUP(C23,Products!A:E,3,0) -> Beauty | I23: =VLOOKUP(C23,Products!A:E,4,0) -> 30 | J23: =_xlfn.XLOOKUP(B23,Customers!A:A,Customers!B:B) -> Kamran Iqbal | K23: =_xlfn.XLOOKUP(B23,Customers!A:A,Customers!C:C) -> Faisalabad | L23: =_xlfn.XLOOKUP(B23,Customers!A:A,Customers!D:D) -> Gold | M23: =D23*I23 -> 30 | N23: =_xlfn.XLOOKUP(C23,Products!A:A,Products!E:E) -> Lahore
A24: O023 | B24: C048 | C24: P14 | D24: 4 | E24: 46124 | F24: Delivered | G24: =VLOOKUP(C24,Products!A:E,2,0) -> Rice Cooker | H24: =VLOOKUP(C24,Products!A:E,3,0) -> Home & Kitchen | I24: =VLOOKUP(C24,Products!A:E,4,0) -> 95 | J24: =_xlfn.XLOOKUP(B24,Customers!A:A,Customers!B:B) -> Nabeel Awan | K24: =_xlfn.XLOOKUP(B24,Customers!A:A,Customers!C:C) -> Islamabad | L24: =_xlfn.XLOOKUP(B24,Customers!A:A,Customers!D:D) -> Bronze | M24: =D24*I24 -> 380 | N24: =_xlfn.XLOOKUP(C24,Products!A:A,Products!E:E) -> Rawalpindi
A25: O024 | B25: C009 | C25: P02 | D25: 1 | E25: 46124 | F25: Delivered | G25: =VLOOKUP(C25,Products!A:E,2,0) -> Wireless Earbuds | H25: =VLOOKUP(C25,Products!A:E,3,0) -> Electronics | I25: =VLOOKUP(C25,Products!A:E,4,0) -> 45 | J25: =_xlfn.XLOOKUP(B25,Customers!A:A,Customers!B:B) -> Bilal Ahmed | K25: =_xlfn.XLOOKUP(B25,Customers!A:A,Customers!C:C) -> Faisalabad | L25: =_xlfn.XLOOKUP(B25,Customers!A:A,Customers!D:D) -> Bronze | M25: =D25*I25 -> 45 | N25: =_xlfn.XLOOKUP(C25,Products!A:A,Products!E:E) -> Lahore
A26: O025 | B26: C025 | C26: P09 | D26: 1 | E26: 46125 | F26: Returned | G26: =VLOOKUP(C26,Products!A:E,2,0) -> Moisturizer | H26: =VLOOKUP(C26,Products!A:E,3,0) -> Beauty | I26: =VLOOKUP(C26,Products!A:E,4,0) -> 25 | J26: =_xlfn.XLOOKUP(B26,Customers!A:A,Customers!B:B) -> Imran Satti | K26: =_xlfn.XLOOKUP(B26,Customers!A:A,Customers!C:C) -> Islamabad | L26: =_xlfn.XLOOKUP(B26,Customers!A:A,Customers!D:D) -> Gold | M26: =D26*I26 -> 25 | N26: =_xlfn.XLOOKUP(C26,Products!A:A,Products!E:E) -> Lahore
A27: O026 | B27: C042 | C27: P13 | D27: 2 | E27: 46125 | F27: Delivered | G27: =VLOOKUP(C27,Products!A:E,2,0) -> Blender | H27: =VLOOKUP(C27,Products!A:E,3,0) -> Home & Kitchen | I27: =VLOOKUP(C27,Products!A:E,4,0) -> 120 | J27: =_xlfn.XLOOKUP(B27,Customers!A:A,Customers!B:B) -> Imran Khan | K27: =_xlfn.XLOOKUP(B27,Customers!A:A,Customers!C:C) -> Rawalpindi | L27: =_xlfn.XLOOKUP(B27,Customers!A:A,Customers!D:D) -> Bronze | M27: =D27*I27 -> 240 | N27: =_xlfn.XLOOKUP(C27,Products!A:A,Products!E:E) -> Islamabad
... A301: O300 | B301: C049 | C301: P13 | D301: 4 | E301: 46262 | F301: Delivered | G301: =VLOOKUP(C301,Products!A:E,2,0) -> Blender | H301: =VLOOKUP(C301,Products!A:E,3,0) -> Home & Kitchen | I301: =VLOOKUP(C301,Products!A:E,4,0) -> 120 | J301: =_xlfn.XLOOKUP(B301,Customers!A:A,Customers!B:B) -> Zeeshan Malik | K301: =_xlfn.XLOOKUP(B301,Customers!A:A,Customers!C:C) -> Karachi | L301: =_xlfn.XLOOKUP(B301,Customers!A:A,Customers!D:D) -> Gold | M301: =D301*I301 -> 480 | N301: =_xlfn.XLOOKUP(C301,Products!A:A,Products!E:E) -> Islamabad

Sheet Products
A1: Product_ID | B1: Product_Name | C1: Category | D1: Unit_Price | E1: Supplier_City
A2: P01 | B2: Smart Watch | C2: Electronics | D2: 200 | E2: Karachi
A3: P02 | B3: Wireless Earbuds | C3: Electronics | D3: 45 | E3: Lahore
A4: P03 | B4: Phone Case | C4: Electronics | D4: 12 | E4: Islamabad
A5: P04 | B5: Bluetooth Speaker | C5: Electronics | D5: 95 | E5: Karachi
A6: P05 | B6: Laptop Stand | C6: Electronics | D6: 40 | E6: Rawalpindi
A7: P06 | B7: Face Serum | C7: Beauty | D7: 30 | E7: Lahore
A8: P07 | B8: Sunscreen | C8: Beauty | D8: 15 | E8: Karachi
A9: P08 | B9: Hair Serum | C9: Beauty | D9: 35 | E9: Islamabad
A10: P09 | B10: Moisturizer | C10: Beauty | D10: 25 | E10: Lahore
A11: P10 | B11: Night Cream | C11: Beauty | D11: 40 | E11: Faisalabad
A12: P11 | B12: Coffee Maker | C12: Home & Kitchen | D12: 110 | E12: Karachi
A13: P12 | B13: Air Fryer | C13: Home & Kitchen | D13: 150 | E13: Lahore
... A16: P15 | B16: Kettle | C16: Home & Kitchen | D16: 65 | E16: Karachi

Sheet Customers
A1: Customer_ID | B1: Customer_Name | C1: City | D1: Membership
A2: C001 | B2: Ahmed Khan | C2: Karachi | D2: Gold
A3: C002 | B3: Sara Ali | C3: Lahore | D3: Silver
A4: C003 | B4: Bilal Raza | C4: Islamabad | D4: Bronze
A5: C004 | B5: Fatima Malik | C5: Karachi | D5: Gold
A6: C005 | B6: Usman Sheikh | C6: Rawalpindi | D6: Silver
A7: C006 | B7: Zainab Hussain | C7: Lahore | D7: Bronze
A8: C007 | B8: Omar Tariq | C8: Karachi | D8: Gold
A9: C008 | B9: Ayesha Siddiqui | C9: Islamabad | D9: Silver
A10: C009 | B10: Bilal Ahmed | C10: Faisalabad | D10: Bronze
A11: C010 | B11: Nadia Qureshi | C11: Lahore | D11: Gold
A12: C011 | B12: Hamza Tariq | C12: Karachi | D12: Silver
... A51: C050 | B51: Sobia Tariq | C51: Lahore | D51: Silver

Sheet Pivot Tables
A3: Row Labels | B3: Sum of Total_Revenue | D3: Row Labels | E3: Sum of Quantity
A4: Home & Kitchen | B4: 21520 | D4: Faisalabad | E4: 17
A5: Grand Total | B5: 21520 | D5: Islamabad | E5: 31
D6: Karachi | E6: 54
D7: Lahore | E7: 53
D8: Rawalpindi | E8: 30
D9: Grand Total | E9: 185
A21: Row Labels | B21: Sum of Total_Revenue
A22: Karachi | B22: 6395
A23: Lahore | B23: 6265
A24: Islamabad | B24: 3465
A25: Rawalpindi | B25: 3360
A26: Faisalabad | B26: 2035
A27: Grand Total | B27: 21520
A33: Count of Order_ID | B33: Column Labels
A34: Row Labels | B34: Delivered | C34: Pending | D34: Returned
A35: Faisalabad | B35: 8
A36: Islamabad | B36: 14 | D36: 2
A37: Karachi | B37: 22 | C37: 1 | D37: 5
A38: Lahore | B38: 23 | C38: 1 | D38: 1
A39: Rawalpindi | B39: 13 | C39: 1 | D39: 3
A40: Grand Total | B40: 80 | C40: 3 | D40: 11
A54: Row Labels | B54: Sum of Total_Revenue
A55: Air Fryer | B55: 6300
A56: Blender | B56: 5400
A57: Coffee Maker | B57: 4840
A58: Rice Cooker | B58: 4655
A59: Kettle | B59: 325
A60: Grand Total | B60: 21520
A74: Row Labels | B74: Sum of Total_Revenue
A75: Gold | B75: 8350
A76: Bronze | B76: 7175
A77: Silver | B77: 5995
A78: Grand Total | B78: 21520
K82: Status | L82: (All)
A84: Row Labels | B84: Sum of Total_Revenue | K84: Sum of Total_Revenue | L84: Count of Order_ID | M84: Sum of Quantity
A85: Karachi | B85: 6395 | K85: 21520 | L85: 94 | M85: 185
A86: Lahore | B86: 6265 | G86: Row Labels | H86: Sum of Total_Revenue
A87: Islamabad | B87: 3465 | G87: Home & Kitchen | H87: 1
A88: Rawalpindi | B88: 3360 | G88: Grand Total | H88: 1
...

Sheet Dashboard
D2: PakCommerce Sales Dashboard | W2: Date as of:
D3: Overview of E-Commerce Performance (Jan – Mar 2026) | W3: 31st March 2026
C6: Total Revenue (PKR) | G6: Total Orders | K6: Average Order Value (PKR) | O6: Total Quantity Sold | S6: Delivery Rate | W6: Top City
B7: =Orders!Q1 -> 21520 | F7: =Orders!Q2 -> 94 | J7: =Orders!Q3 -> 228.93617 | N7: =Orders!Q15 -> 185 | R7: =Orders!Q13 -> 0.88 | V7: =Orders!Q4 -> Lahore
C8: Jan-Mar 2026 | G8: Jan-Mar 2026 | K8: Jan-Mar 2026 | O8: Jan-Mar 2026 | S8: Jan-Mar 2026 | W8: =TEXT(SUMIF(Orders!K2:K301,"Lahore",Orders!M2:M301)/SUM(Orders!M2:M301),"0.0%")&" of Total Revenue" -> 29.3% of Total Revenue
W10: FILTERS
B41: ABOUT THIS DASHBOARD | F41: NOTES | I41: TOOLS USED IN EXCEL | N41: COLOR GUIDE
B42: This dashboard provides key insights into | F42: - Revenue is in PKR | I42: - Pivot Tables for data summary | O42: Dark navy box → label "Primary"
B43: PakCommerce sales performance for the | F43: - All values are rounded | I43: - Pivot Charts for visualizations | O43: Blue box → label "Charts"
B44: period Jan – Mar 2026. Data is summarized | F44: - Data source: Sample dataset | I44: - Slicers for interactivity | O44: Green box → label "Positive"
B45: from Orders, Products and Customers datasets. | F45: - 300 orders analyzed | I45: - VLOOKUP & XLOOKUP for data connection | O45: Orange box → label "Alert"
I46: - SUMIF, COUNTIF for calculations | O46: Red box → label "Negative"
I47: - INDEX MATCH for dynamic KPIs
